{
    DataVersion: 3955,
    size: [11, 3, 3],
    data: [
        {pos: [10, 0, 0], state: "ae2:energy_cell{fullness:4}", nbt: {id: "ae2:energy_cell", internalCurrentPower: 200000.0d}},
        {pos: [9, 0, 0], state: "ae2:cable_bus{light_level:0,waterlogged:false}", nbt: {cable: {id: "ae2:purple_glass_cable", visual: {connections: ["east", "up", "west"], missingChannel: 0b, powered: 1b}}, hasRedstone: 2, id: "ae2:cable_bus", visual: {}, north: {id: "ae2:crafting_terminal", visual: {missingChannel: 0b, powered: 1b}}}},
        {pos: [8, 0, 0], state: "ae2federation:router"},
        {pos: [7, 0, 0], state: "ae2federation:cable"},
        {pos: [6, 0, 0], state: "ae2federation:cable"},
        {pos: [5, 0, 0], state: "ae2federation:router"},
        {pos: [4, 0, 0], state: "ae2:cable_bus{light_level:0,waterlogged:false}", nbt: {cable: {id: "ae2:light_blue_glass_cable", visual: {connections: ["east", "up", "west"], missingChannel: 0b, powered: 1b}}, hasRedstone: 2, id: "ae2:cable_bus", visual: {}}},
        {pos: [3, 0, 0], state: "extendedae:assembler_matrix_frame{powered:true,shape:block}"},
        {pos: [2, 0, 0], state: "extendedae:assembler_matrix_frame{powered:true,shape:column_x}"},
        {pos: [1, 0, 0], state: "extendedae:assembler_matrix_frame{powered:true,shape:column_x}"},
        {pos: [0, 0, 0], state: "extendedae:assembler_matrix_frame{powered:true,shape:block}"},
        {pos: [3, 0, 1], state: "extendedae:assembler_matrix_frame{powered:true,shape:column_z}"},
        {pos: [2, 0, 1], state: "extendedae:assembler_matrix_wall"},
        {pos: [1, 0, 1], state: "extendedae:assembler_matrix_wall"},
        {pos: [0, 0, 1], state: "extendedae:assembler_matrix_frame{powered:true,shape:column_z}"},
        {pos: [3, 0, 2], state: "extendedae:assembler_matrix_frame{powered:true,shape:block}"},
        {pos: [2, 0, 2], state: "extendedae:assembler_matrix_frame{powered:true,shape:column_x}"},
        {pos: [1, 0, 2], state: "extendedae:assembler_matrix_frame{powered:true,shape:column_x}"},
        {pos: [0, 0, 2], state: "extendedae:assembler_matrix_frame{powered:true,shape:block}"},
        {pos: [10, 1, 0], state: "ae2:drive{facing:north,spin:0}", nbt: {id: "ae2:drive", priority: 0, visual: {cell0: {id: "ae2:item_storage_cell_4k", state: "not_empty"}, cell1: {id: "ae2:item_storage_cell_4k", state: "not_empty"}, cell2: {id: "ae2:item_storage_cell_4k", state: "not_empty"}, cell3: {id: "ae2:item_storage_cell_4k", state: "not_empty"}}}},
        {pos: [9, 1, 0], state: "ae2:1k_crafting_storage{formed:true,powered:true}", nbt: {core: 1b, id: "ae2:crafting_storage", visual: {}}},
        {pos: [4, 1, 0], state: "ae2:energy_cell{fullness:4}", nbt: {id: "ae2:energy_cell", internalCurrentPower: 200000.0d}},
        {pos: [3, 1, 0], state: "extendedae:assembler_matrix_frame{powered:true,shape:column_y}"},
        {pos: [2, 1, 0], state: "extendedae:assembler_matrix_wall"},
        {pos: [1, 1, 0], state: "extendedae:assembler_matrix_wall"},
        {pos: [0, 1, 0], state: "extendedae:assembler_matrix_frame{powered:true,shape:column_y}"},
        {pos: [3, 1, 1], state: "extendedae:assembler_matrix_wall"},
        {pos: [2, 1, 1], state: "extendedae:assembler_matrix_crafter"},
        {pos: [1, 1, 1], state: "extendedae:assembler_matrix_pattern"},
        {pos: [0, 1, 1], state: "extendedae:assembler_matrix_wall"},
        {pos: [3, 1, 2], state: "extendedae:assembler_matrix_frame{powered:true,shape:column_y}"},
        {pos: [2, 1, 2], state: "extendedae:assembler_matrix_wall"},
        {pos: [1, 1, 2], state: "extendedae:assembler_matrix_wall"},
        {pos: [0, 1, 2], state: "extendedae:assembler_matrix_frame{powered:true,shape:column_y}"},
        {pos: [3, 2, 0], state: "extendedae:assembler_matrix_frame{powered:true,shape:block}"},
        {pos: [2, 2, 0], state: "extendedae:assembler_matrix_frame{powered:true,shape:column_x}"},
        {pos: [1, 2, 0], state: "extendedae:assembler_matrix_frame{powered:true,shape:column_x}"},
        {pos: [0, 2, 0], state: "extendedae:assembler_matrix_frame{powered:true,shape:block}"},
        {pos: [3, 2, 1], state: "extendedae:assembler_matrix_frame{powered:true,shape:column_z}"},
        {pos: [2, 2, 1], state: "extendedae:assembler_matrix_wall"},
        {pos: [1, 2, 1], state: "extendedae:assembler_matrix_wall"},
        {pos: [0, 2, 1], state: "extendedae:assembler_matrix_frame{powered:true,shape:column_z}"},
        {pos: [3, 2, 2], state: "extendedae:assembler_matrix_frame{powered:true,shape:block}"},
        {pos: [2, 2, 2], state: "extendedae:assembler_matrix_frame{powered:true,shape:column_x}"},
        {pos: [1, 2, 2], state: "extendedae:assembler_matrix_frame{powered:true,shape:column_x}"},
        {pos: [0, 2, 2], state: "extendedae:assembler_matrix_frame{powered:true,shape:block}"}
    ],
    entities: [],
    palette: [
        "ae2:energy_cell{fullness:4}",
        "ae2:cable_bus{light_level:0,waterlogged:false}",
        "ae2federation:router",
        "ae2federation:cable",
        "extendedae:assembler_matrix_frame{powered:true,shape:block}",
        "extendedae:assembler_matrix_frame{powered:true,shape:column_x}",
        "extendedae:assembler_matrix_frame{powered:true,shape:column_z}",
        "extendedae:assembler_matrix_wall",
        "ae2:drive{facing:north,spin:0}",
        "ae2:1k_crafting_storage{formed:true,powered:true}",
        "extendedae:assembler_matrix_frame{powered:true,shape:column_y}",
        "extendedae:assembler_matrix_crafter",
        "extendedae:assembler_matrix_pattern"
    ]
}
