{
    DataVersion: 3955,
    size: [10, 3, 3],
    data: [
        {pos: [0, 0, 0], state: "neoecoae:storage_casing{formed:true,invisible:false}", nbt: {proxy: {p: 0}, visual: {}, id: "neoecoae:storage_casing"}},
        {pos: [1, 0, 0], state: "neoecoae:eco_drive{facing:north,formed:true,has_cell:false}", nbt: {proxy: {p: 0}, managed: {cellStack: "_NULL_"}, visual: {}, id: "neoecoae:eco_drive"}},
        {pos: [2, 0, 0], state: "neoecoae:storage_casing{formed:true,invisible:true}", nbt: {proxy: {p: 0}, visual: {}, id: "neoecoae:storage_casing"}},
        {pos: [3, 0, 0], state: "neoecoae:storage_casing{formed:true,invisible:true}", nbt: {proxy: {p: 0}, visual: {}, id: "neoecoae:storage_casing"}},
        {pos: [4, 0, 0], state: "neoecoae:storage_casing{formed:true,invisible:true}", nbt: {proxy: {p: 0}, visual: {}, id: "neoecoae:storage_casing"}},
        {pos: [0, 0, 1], state: "neoecoae:storage_casing{formed:true,invisible:false}", nbt: {proxy: {p: 0}, visual: {}, id: "neoecoae:storage_casing"}},
        {pos: [1, 0, 1], state: "neoecoae:energy_cell_l4{facing:south,formed:true,level:0}", nbt: {proxy: {p: 0}, managed: {energyStored: 0.0d, neighborChangePending: 0b}, visual: {}, id: "neoecoae:energy_cell_l4"}},
        {pos: [2, 0, 1], state: "neoecoae:storage_casing{formed:true,invisible:true}", nbt: {proxy: {p: 0}, visual: {}, id: "neoecoae:storage_casing"}},
        {pos: [3, 0, 1], state: "neoecoae:storage_casing{formed:true,invisible:true}", nbt: {proxy: {p: 0}, visual: {}, id: "neoecoae:storage_casing"}},
        {pos: [4, 0, 1], state: "neoecoae:storage_casing{formed:true,invisible:true}", nbt: {proxy: {p: 0}, visual: {}, id: "neoecoae:storage_casing"}},
        {pos: [5, 0, 2], state: "ae2:energy_cell{fullness:4}", nbt: {id: "ae2:energy_cell", internalCurrentPower: 200000.0d}},
        {pos: [0, 1, 0], state: "neoecoae:storage_casing{formed:true,invisible:false}", nbt: {proxy: {p: 0}, visual: {}, id: "neoecoae:storage_casing"}},
        {pos: [1, 1, 0], state: "neoecoae:eco_drive{facing:north,formed:true,has_cell:false}", nbt: {proxy: {p: 0}, managed: {cellStack: "_NULL_"}, visual: {}, id: "neoecoae:eco_drive"}},
        {pos: [2, 1, 0], state: "neoecoae:storage_casing{formed:true,invisible:true}", nbt: {proxy: {p: 0}, visual: {}, id: "neoecoae:storage_casing"}},
        {pos: [3, 1, 0], state: "neoecoae:storage_system_l4{facing:north,formed:true,mirrored:false,storage_mode:storage}", nbt: {proxy: {p: 0}, infiniteHostMode: "formed_normal", managed: {infiniteComponentInventory: {}, hostMode: "FORMED_NORMAL", mirrorBuild: 0b, storagePriority: 0, selectedBuildLength: 1, infiniteDomainId: "_NULL_"}, visual: {}, id: "neoecoae:storage_system_l4"}},
        {pos: [4, 1, 0], state: "neoecoae:storage_casing{formed:true,invisible:true}", nbt: {proxy: {p: 0}, visual: {}, id: "neoecoae:storage_casing"}},
        {pos: [0, 1, 1], state: "neoecoae:storage_casing{formed:true,invisible:false}", nbt: {proxy: {p: 0}, visual: {}, id: "neoecoae:storage_casing"}},
        {pos: [1, 1, 1], state: "neoecoae:storage_vent{facing:south,formed:true}", nbt: {proxy: {p: 0}, visual: {}, id: "neoecoae:storage_vent"}},
        {pos: [2, 1, 1], state: "neoecoae:storage_casing{formed:true,invisible:true}", nbt: {proxy: {p: 0}, visual: {}, id: "neoecoae:storage_casing"}},
        {pos: [3, 1, 1], state: "neoecoae:storage_casing{formed:true,invisible:true}", nbt: {proxy: {p: 0}, visual: {}, id: "neoecoae:storage_casing"}},
        {pos: [4, 1, 1], state: "neoecoae:storage_interface{formed:true,storage_mode:storage}", nbt: {proxy: {p: 0}, managed: {storageInterfaceMode: "STORAGE"}, visual: {}, id: "neoecoae:storage_interface"}},
        {pos: [4, 1, 2], state: "ae2:cable_bus{light_level:0,waterlogged:false}", nbt: {cable: {id: "ae2:green_smart_cable", visual: {channelsEast: 1, channelsNorth: 1, connections: ["north", "east"], missingChannel: 0b, powered: 1b}}, hasRedstone: 2, id: "ae2:cable_bus", visual: {}}},
        {pos: [5, 1, 2], state: "ae2:cable_bus{light_level:0,waterlogged:false}", nbt: {cable: {id: "ae2:green_smart_cable", visual: {channelsDown: 1, channelsEast: 1, channelsWest: 1, connections: ["west", "down", "east"], missingChannel: 0b, powered: 1b}}, hasRedstone: 2, id: "ae2:cable_bus", visual: {}}},
        {pos: [6, 1, 2], state: "ae2:cable_bus{light_level:0,waterlogged:false}", nbt: {cable: {id: "ae2:light_blue_smart_cable", visual: {channelsEast: 0, connections: ["east"], missingChannel: 0b, powered: 1b}}, hasRedstone: 2, id: "ae2:cable_bus", visual: {}, west: {id: "ae2federation:bridge", visual: {missingChannel: 0b, powered: 1b}}}},
        {pos: [7, 1, 2], state: "ae2:cable_bus{light_level:0,waterlogged:false}", nbt: {cable: {id: "ae2:light_blue_smart_cable", visual: {channelsEast: 0, channelsWest: 0, connections: ["west", "east"], missingChannel: 0b, powered: 1b}}, hasRedstone: 2, id: "ae2:cable_bus", visual: {}}},
        {pos: [8, 1, 2], state: "ae2:cable_bus{light_level:0,waterlogged:false}", nbt: {cable: {id: "ae2:purple_smart_cable", visual: {channelsEast: 1, connections: ["east"], missingChannel: 0b, powered: 1b}}, hasRedstone: 2, id: "ae2:cable_bus", visual: {}, west: {id: "ae2federation:bridge", visual: {missingChannel: 0b, powered: 1b}}}},
        {pos: [9, 1, 2], state: "ae2:cable_bus{light_level:0,waterlogged:false}", nbt: {cable: {id: "ae2:purple_smart_cable", visual: {channelsWest: 1, connections: ["west"], missingChannel: 0b, powered: 1b}}, hasRedstone: 2, id: "ae2:cable_bus", visual: {}, north: {id: "ae2:terminal", visual: {missingChannel: 0b, powered: 1b}}}},
        {pos: [0, 2, 0], state: "neoecoae:storage_casing{formed:true,invisible:false}", nbt: {proxy: {p: 0}, visual: {}, id: "neoecoae:storage_casing"}},
        {pos: [1, 2, 0], state: "neoecoae:eco_drive{facing:north,formed:true,has_cell:false}", nbt: {proxy: {p: 0}, managed: {cellStack: "_NULL_"}, visual: {}, id: "neoecoae:eco_drive"}},
        {pos: [2, 2, 0], state: "neoecoae:storage_casing{formed:true,invisible:true}", nbt: {proxy: {p: 0}, visual: {}, id: "neoecoae:storage_casing"}},
        {pos: [3, 2, 0], state: "neoecoae:storage_casing{formed:true,invisible:true}", nbt: {proxy: {p: 0}, visual: {}, id: "neoecoae:storage_casing"}},
        {pos: [4, 2, 0], state: "neoecoae:storage_casing{formed:true,invisible:true}", nbt: {proxy: {p: 0}, visual: {}, id: "neoecoae:storage_casing"}},
        {pos: [0, 2, 1], state: "neoecoae:storage_casing{formed:true,invisible:false}", nbt: {proxy: {p: 0}, visual: {}, id: "neoecoae:storage_casing"}},
        {pos: [1, 2, 1], state: "neoecoae:energy_cell_l4{facing:south,formed:true,level:0}", nbt: {proxy: {p: 0}, managed: {energyStored: 0.0d, neighborChangePending: 0b}, visual: {}, id: "neoecoae:energy_cell_l4"}},
        {pos: [2, 2, 1], state: "neoecoae:storage_casing{formed:true,invisible:true}", nbt: {proxy: {p: 0}, visual: {}, id: "neoecoae:storage_casing"}},
        {pos: [3, 2, 1], state: "neoecoae:storage_casing{formed:true,invisible:true}", nbt: {proxy: {p: 0}, visual: {}, id: "neoecoae:storage_casing"}},
        {pos: [4, 2, 1], state: "neoecoae:storage_casing{formed:true,invisible:true}", nbt: {proxy: {p: 0}, visual: {}, id: "neoecoae:storage_casing"}}
    ],
    entities: [],
    palette: [
        "neoecoae:storage_casing{formed:true,invisible:false}",
        "neoecoae:eco_drive{facing:north,formed:true,has_cell:false}",
        "neoecoae:storage_casing{formed:true,invisible:true}",
        "neoecoae:energy_cell_l4{facing:south,formed:true,level:0}",
        "ae2:energy_cell{fullness:4}",
        "neoecoae:storage_system_l4{facing:north,formed:true,mirrored:false,storage_mode:storage}",
        "neoecoae:storage_vent{facing:south,formed:true}",
        "neoecoae:storage_interface{formed:true,storage_mode:storage}",
        "ae2:cable_bus{light_level:0,waterlogged:false}"
    ]
}
