{
    DataVersion: 3955,
    size: [7, 4, 10],
    data: [
        {pos: [0, 0, 4], state: "molecularmanipulator:matter_fabrication_casing{facing:north}"},
        {pos: [1, 0, 4], state: "molecularmanipulator:matter_fabrication_casing{facing:north}"},
        {pos: [2, 0, 4], state: "molecularmanipulator:matter_fabrication_casing{facing:north}"},
        {pos: [3, 0, 4], state: "molecularmanipulator:matter_fabrication_casing{facing:north}"},
        {pos: [4, 0, 4], state: "molecularmanipulator:matter_fabrication_casing{facing:north}"},
        {pos: [5, 0, 4], state: "molecularmanipulator:matter_fabrication_casing{facing:north}"},
        {pos: [6, 0, 4], state: "molecularmanipulator:matter_fabrication_casing{facing:north}"},
        {pos: [0, 0, 5], state: "molecularmanipulator:matter_fabrication_casing{facing:north}"},
        {pos: [1, 0, 5], state: "molecularmanipulator:matter_fabrication_casing{facing:north}"},
        {pos: [2, 0, 5], state: "molecularmanipulator:matter_fabrication_casing{facing:north}"},
        {pos: [3, 0, 5], state: "molecularmanipulator:matter_fabrication_casing{facing:north}"},
        {pos: [4, 0, 5], state: "molecularmanipulator:matter_fabrication_casing{facing:north}"},
        {pos: [5, 0, 5], state: "molecularmanipulator:matter_fabrication_casing{facing:north}"},
        {pos: [6, 0, 5], state: "molecularmanipulator:matter_fabrication_casing{facing:north}"},
        {pos: [0, 0, 6], state: "molecularmanipulator:matter_fabrication_casing{facing:north}"},
        {pos: [1, 0, 6], state: "molecularmanipulator:matter_fabrication_casing{facing:north}"},
        {pos: [2, 0, 6], state: "molecularmanipulator:matter_fabrication_casing{facing:north}"},
        {pos: [3, 0, 6], state: "molecularmanipulator:matter_fabrication_casing{facing:north}"},
        {pos: [4, 0, 6], state: "molecularmanipulator:matter_fabrication_casing{facing:north}"},
        {pos: [5, 0, 6], state: "molecularmanipulator:matter_fabrication_casing{facing:north}"},
        {pos: [6, 0, 6], state: "molecularmanipulator:matter_fabrication_casing{facing:north}"},
        {pos: [0, 0, 7], state: "molecularmanipulator:matter_fabrication_casing{facing:north}"},
        {pos: [1, 0, 7], state: "molecularmanipulator:matter_fabrication_casing{facing:north}"},
        {pos: [2, 0, 7], state: "molecularmanipulator:matter_fabrication_casing{facing:north}"},
        {pos: [3, 0, 7], state: "molecularmanipulator:matter_fabrication_casing{facing:north}"},
        {pos: [4, 0, 7], state: "molecularmanipulator:matter_fabrication_casing{facing:north}"},
        {pos: [5, 0, 7], state: "molecularmanipulator:matter_fabrication_casing{facing:north}"},
        {pos: [6, 0, 7], state: "molecularmanipulator:matter_fabrication_casing{facing:north}"},
        {pos: [0, 0, 8], state: "molecularmanipulator:matter_fabrication_casing{facing:north}"},
        {pos: [1, 0, 8], state: "molecularmanipulator:matter_fabrication_casing{facing:north}"},
        {pos: [2, 0, 8], state: "molecularmanipulator:matter_fabrication_casing{facing:north}"},
        {pos: [3, 0, 8], state: "molecularmanipulator:matter_fabrication_casing{facing:north}"},
        {pos: [4, 0, 8], state: "molecularmanipulator:matter_fabrication_casing{facing:north}"},
        {pos: [5, 0, 8], state: "molecularmanipulator:matter_fabrication_casing{facing:north}"},
        {pos: [6, 0, 8], state: "molecularmanipulator:matter_fabrication_casing{facing:north}"},
        {pos: [0, 0, 9], state: "molecularmanipulator:matter_fabrication_casing{facing:north}"},
        {pos: [1, 0, 9], state: "molecularmanipulator:matter_fabrication_casing{facing:north}"},
        {pos: [2, 0, 9], state: "molecularmanipulator:matter_fabrication_casing{facing:north}"},
        {pos: [3, 0, 9], state: "molecularmanipulator:matter_fabrication_casing{facing:north}"},
        {pos: [4, 0, 9], state: "molecularmanipulator:matter_fabrication_casing{facing:north}"},
        {pos: [5, 0, 9], state: "molecularmanipulator:matter_fabrication_casing{facing:north}"},
        {pos: [6, 0, 9], state: "molecularmanipulator:matter_fabrication_casing{facing:north}"},
        {pos: [3, 1, 0], state: "ae2:energy_cell{fullness:4}", nbt: {id: "ae2:energy_cell", internalCurrentPower: 200000.0d}},
        {pos: [0, 1, 5], state: "molecularmanipulator:matter_fabrication_casing{facing:north}"},
        {pos: [1, 1, 5], state: "molecularmanipulator:matter_fabrication_casing{facing:north}"},
        {pos: [5, 1, 5], state: "molecularmanipulator:matter_fabrication_casing{facing:north}"},
        {pos: [6, 1, 5], state: "molecularmanipulator:matter_fabrication_casing{facing:north}"},
        {pos: [0, 1, 6], state: "molecularmanipulator:matter_fabrication_casing{facing:north}"},
        {pos: [1, 1, 6], state: "molecularmanipulator:matter_fabrication_casing{facing:north}"},
        {pos: [5, 1, 6], state: "molecularmanipulator:matter_fabrication_casing{facing:north}"},
        {pos: [6, 1, 6], state: "molecularmanipulator:matter_fabrication_casing{facing:north}"},
        {pos: [0, 1, 7], state: "molecularmanipulator:matter_fabrication_casing{facing:north}"},
        {pos: [1, 1, 7], state: "molecularmanipulator:matter_fabrication_casing{facing:north}"},
        {pos: [5, 1, 7], state: "molecularmanipulator:matter_fabrication_casing{facing:north}"},
        {pos: [6, 1, 7], state: "molecularmanipulator:matter_fabrication_casing{facing:north}"},
        {pos: [0, 1, 8], state: "molecularmanipulator:matter_fabrication_casing{facing:north}"},
        {pos: [1, 1, 8], state: "molecularmanipulator:matter_fabrication_casing{facing:north}"},
        {pos: [2, 1, 8], state: "molecularmanipulator:matter_fabrication_casing{facing:north}"},
        {pos: [3, 1, 8], state: "molecularmanipulator:matter_fabrication_casing{facing:north}"},
        {pos: [4, 1, 8], state: "molecularmanipulator:matter_fabrication_casing{facing:north}"},
        {pos: [5, 1, 8], state: "molecularmanipulator:matter_fabrication_casing{facing:north}"},
        {pos: [6, 1, 8], state: "molecularmanipulator:matter_fabrication_casing{facing:north}"},
        {pos: [0, 1, 9], state: "molecularmanipulator:matter_fabrication_casing{facing:north}"},
        {pos: [1, 1, 9], state: "molecularmanipulator:matter_fabrication_casing{facing:north}"},
        {pos: [2, 1, 9], state: "molecularmanipulator:matter_fabrication_casing{facing:north}"},
        {pos: [3, 1, 9], state: "molecularmanipulator:matter_fabrication_casing{facing:north}"},
        {pos: [4, 1, 9], state: "molecularmanipulator:matter_fabrication_casing{facing:north}"},
        {pos: [5, 1, 9], state: "molecularmanipulator:matter_fabrication_casing{facing:north}"},
        {pos: [6, 1, 9], state: "molecularmanipulator:matter_fabrication_casing{facing:north}"},
        {pos: [2, 2, 0], state: "ae2:drive{facing:north,spin:0}", nbt: {id: "ae2:drive", priority: 0, visual: {cell0: {id: "ae2:item_storage_cell_4k", state: "not_empty"}, cell1: {id: "ae2:item_storage_cell_4k", state: "not_empty"}, cell2: {id: "ae2:item_storage_cell_4k", state: "not_empty"}, cell3: {id: "ae2:item_storage_cell_4k", state: "not_empty"}}}},
        {pos: [3, 2, 0], state: "ae2:cable_bus{light_level:0,waterlogged:false}", nbt: {cable: {id: "ae2:purple_glass_cable", visual: {connections: ["down", "east", "south", "west"], missingChannel: 0b, powered: 1b}}, hasRedstone: 2, id: "ae2:cable_bus", visual: {}, north: {id: "ae2:crafting_terminal", visual: {missingChannel: 0b, powered: 1b}}}},
        {pos: [4, 2, 0], state: "ae2:1k_crafting_storage{formed:true,powered:true}", nbt: {core: 1b, id: "ae2:crafting_storage", visual: {}}},
        {pos: [3, 2, 1], state: "ae2federation:router"},
        {pos: [3, 2, 2], state: "ae2:cable_bus{light_level:0,waterlogged:false}", nbt: {cable: {id: "ae2:light_blue_glass_cable", visual: {connections: ["north", "south"], missingChannel: 0b, powered: 1b}}, hasRedstone: 2, id: "ae2:cable_bus", visual: {}}},
        {pos: [3, 2, 3], state: "ae2:cable_bus{light_level:0,waterlogged:false}", nbt: {cable: {id: "ae2:light_blue_glass_cable", visual: {connections: ["north", "south"], missingChannel: 0b, powered: 1b}}, hasRedstone: 2, id: "ae2:cable_bus", visual: {}}},
        {pos: [0, 2, 4], state: "molecularmanipulator:matter_fabrication_casing{facing:north}"},
        {pos: [1, 2, 4], state: "molecularmanipulator:matter_fabrication_casing{facing:north}"},
        {pos: [3, 2, 4], state: "ae2:cable_bus{light_level:0,waterlogged:false}", nbt: {cable: {id: "ae2:light_blue_glass_cable", visual: {connections: ["north", "south"], missingChannel: 0b, powered: 1b}}, hasRedstone: 2, id: "ae2:cable_bus", visual: {}}},
        {pos: [5, 2, 4], state: "molecularmanipulator:matter_fabrication_pattern_assembly{push_direction:all}"},
        {pos: [6, 2, 4], state: "molecularmanipulator:matter_fabrication_casing{facing:north}"},
        {pos: [0, 2, 5], state: "molecularmanipulator:matter_fabrication_casing{facing:north}"},
        {pos: [1, 2, 5], state: "molecularmanipulator:matter_fabrication_casing{facing:north}"},
        {pos: [3, 2, 5], state: "ae2:cable_bus{light_level:0,waterlogged:false}", nbt: {cable: {id: "ae2:light_blue_glass_cable", visual: {connections: ["north", "south"], missingChannel: 0b, powered: 1b}}, hasRedstone: 2, id: "ae2:cable_bus", visual: {}}},
        {pos: [5, 2, 5], state: "molecularmanipulator:matter_fabrication_casing{facing:north}"},
        {pos: [6, 2, 5], state: "molecularmanipulator:matter_fabrication_casing{facing:north}"},
        {pos: [0, 2, 6], state: "molecularmanipulator:matter_fabrication_coil{facing:north}"},
        {pos: [1, 2, 6], state: "molecularmanipulator:matter_fabrication_coil{facing:north}"},
        {pos: [3, 2, 6], state: "ae2:cable_bus{light_level:0,waterlogged:false}", nbt: {cable: {id: "ae2:light_blue_glass_cable", visual: {connections: ["north", "south"], missingChannel: 0b, powered: 1b}}, hasRedstone: 2, id: "ae2:cable_bus", visual: {}}},
        {pos: [5, 2, 6], state: "molecularmanipulator:matter_fabrication_coil{facing:north}"},
        {pos: [6, 2, 6], state: "molecularmanipulator:matter_fabrication_coil{facing:north}"},
        {pos: [0, 2, 7], state: "molecularmanipulator:matter_fabrication_casing{facing:north}"},
        {pos: [1, 2, 7], state: "molecularmanipulator:matter_fabrication_casing{facing:north}"},
        {pos: [3, 2, 7], state: "ae2:cable_bus{light_level:0,waterlogged:false}", nbt: {cable: {id: "ae2:light_blue_glass_cable", visual: {connections: ["north", "south"], missingChannel: 0b, powered: 1b}}, hasRedstone: 2, id: "ae2:cable_bus", visual: {}}},
        {pos: [5, 2, 7], state: "molecularmanipulator:matter_fabrication_casing{facing:north}"},
        {pos: [6, 2, 7], state: "molecularmanipulator:matter_fabrication_casing{facing:north}"},
        {pos: [0, 2, 8], state: "molecularmanipulator:matter_fabrication_casing{facing:north}"},
        {pos: [1, 2, 8], state: "molecularmanipulator:matter_fabrication_casing{facing:north}"},
        {pos: [2, 2, 8], state: "molecularmanipulator:matter_fabrication_casing{facing:north}"},
        {pos: [3, 2, 8], state: "molecularmanipulator:matter_fabrication_controller{facing:north,powered:true}"},
        {pos: [4, 2, 8], state: "molecularmanipulator:matter_fabrication_casing{facing:north}"},
        {pos: [5, 2, 8], state: "molecularmanipulator:matter_fabrication_casing{facing:north}"},
        {pos: [6, 2, 8], state: "molecularmanipulator:matter_fabrication_casing{facing:north}"},
        {pos: [0, 2, 9], state: "molecularmanipulator:matter_fabrication_casing{facing:north}"},
        {pos: [1, 2, 9], state: "molecularmanipulator:matter_fabrication_casing{facing:north}"},
        {pos: [2, 2, 9], state: "molecularmanipulator:matter_fabrication_casing{facing:north}"},
        {pos: [3, 2, 9], state: "molecularmanipulator:matter_fabrication_coil{facing:north}"},
        {pos: [4, 2, 9], state: "molecularmanipulator:matter_fabrication_casing{facing:north}"},
        {pos: [5, 2, 9], state: "molecularmanipulator:matter_fabrication_casing{facing:north}"},
        {pos: [6, 2, 9], state: "molecularmanipulator:matter_fabrication_casing{facing:north}"},
        {pos: [0, 3, 7], state: "molecularmanipulator:matter_fabrication_casing{facing:north}"},
        {pos: [6, 3, 7], state: "molecularmanipulator:matter_fabrication_casing{facing:north}"},
        {pos: [0, 3, 8], state: "molecularmanipulator:matter_fabrication_casing{facing:north}"},
        {pos: [1, 3, 8], state: "molecularmanipulator:matter_fabrication_core{facing:north}"},
        {pos: [3, 3, 8], state: "molecularmanipulator:matter_fabrication_casing{facing:north}"},
        {pos: [5, 3, 8], state: "molecularmanipulator:matter_fabrication_core{facing:north}"},
        {pos: [6, 3, 8], state: "molecularmanipulator:matter_fabrication_casing{facing:north}"},
        {pos: [0, 3, 9], state: "molecularmanipulator:matter_fabrication_casing{facing:north}"},
        {pos: [1, 3, 9], state: "molecularmanipulator:matter_fabrication_coil{facing:north}"},
        {pos: [5, 3, 9], state: "molecularmanipulator:matter_fabrication_coil{facing:north}"},
        {pos: [6, 3, 9], state: "molecularmanipulator:matter_fabrication_casing{facing:north}"}
    ],
    entities: [],
    palette: [
        "molecularmanipulator:matter_fabrication_casing{facing:north}",
        "ae2:energy_cell{fullness:4}",
        "ae2:drive{facing:north,spin:0}",
        "ae2:cable_bus{light_level:0,waterlogged:false}",
        "ae2:1k_crafting_storage{formed:true,powered:true}",
        "ae2federation:router",
        "molecularmanipulator:matter_fabrication_pattern_assembly{push_direction:all}",
        "molecularmanipulator:matter_fabrication_coil{facing:north}",
        "molecularmanipulator:matter_fabrication_controller{facing:north,powered:true}",
        "molecularmanipulator:matter_fabrication_core{facing:north}"
    ]
}
