{
    DataVersion: 3955,
    size: [7, 3, 4],
    data: [
        {pos: [6, 0, 0], state: "ae2:cable_bus{light_level:0,waterlogged:false}", nbt: {cable: {id: "ae2:purple_smart_cable", visual: {channelsWest: 1, connections: ["west"], missingChannel: 0b, powered: 1b}}, hasRedstone: 2, id: "ae2:cable_bus", visual: {}, north: {id: "ae2:terminal", visual: {missingChannel: 0b, powered: 1b}}}},
        {pos: [5, 0, 0], state: "ae2federation:switch"},
        {pos: [4, 0, 0], state: "ae2:cable_bus{light_level:0,waterlogged:false}", nbt: {cable: {id: "ae2:light_blue_smart_cable", visual: {channelsEast: 2, channelsUp: 2, channelsWest: 2, connections: ["up", "west", "east"], missingChannel: 0b, powered: 1b}}, hasRedstone: 2, id: "ae2:cable_bus", visual: {}}},
        {pos: [3, 0, 0], state: "ae2:cable_bus{light_level:0,waterlogged:false}", nbt: {cable: {id: "ae2:light_blue_smart_cable", visual: {channelsEast: 2, channelsUp: 2, channelsWest: 2, connections: ["up", "west", "east"], missingChannel: 0b, powered: 1b}}, hasRedstone: 2, id: "ae2:cable_bus", visual: {}}},
        {pos: [2, 0, 0], state: "ae2:cable_bus{light_level:0,waterlogged:false}", nbt: {cable: {id: "ae2:light_blue_smart_cable", visual: {channelsEast: 2, channelsWest: 2, connections: ["west", "east"], missingChannel: 0b, powered: 1b}}, hasRedstone: 2, id: "ae2:cable_bus", visual: {}}},
        {pos: [1, 0, 0], state: "ae2:cable_bus{light_level:0,waterlogged:false}", nbt: {cable: {id: "ae2:light_blue_smart_cable", visual: {channelsEast: 2, channelsUp: 2, connections: ["up", "east"], missingChannel: 0b, powered: 1b}}, hasRedstone: 2, id: "ae2:cable_bus", visual: {}}},
        {pos: [4, 1, 0], state: "ae2:energy_cell{fullness:4}", nbt: {id: "ae2:energy_cell", internalCurrentPower: 200000.0d}},
        {pos: [3, 1, 0], state: "ae2:drive{facing:north,spin:0}", nbt: {id: "ae2:drive", priority: 0, visual: {cell0: {id: "appmek:chemical_storage_cell_1k", state: "not_empty"}, cell1: {id: "appmek:chemical_storage_cell_1k", state: "not_empty"}, cell2: {id: "appmek:chemical_storage_cell_1k", state: "not_empty"}}}},
        {pos: [1, 1, 0], state: "ae2:cable_bus{light_level:0,waterlogged:false}", nbt: {cable: {id: "ae2:light_blue_smart_cable", visual: {channelsDown: 2, connections: ["down"], missingChannel: 0b, powered: 1b}}, hasRedstone: 2, id: "ae2:cable_bus", visual: {}, south: {id: "ae2:storage_bus", visual: {missingChannel: 0b, powered: 1b}}}},
        {pos: [2, 0, 1], state: "mekanism:dynamic_tank"},
        {pos: [1, 0, 1], state: "mekanism:dynamic_tank"},
        {pos: [0, 0, 1], state: "mekanism:dynamic_tank"},
        {pos: [2, 1, 1], state: "mekanism:dynamic_tank"},
        {pos: [1, 1, 1], state: "mekanism:dynamic_valve"},
        {pos: [0, 1, 1], state: "mekanism:dynamic_tank"},
        {pos: [2, 2, 1], state: "mekanism:dynamic_tank"},
        {pos: [1, 2, 1], state: "mekanism:dynamic_tank"},
        {pos: [0, 2, 1], state: "mekanism:dynamic_tank"},
        {pos: [2, 0, 2], state: "mekanism:dynamic_tank"},
        {pos: [1, 0, 2], state: "mekanism:dynamic_tank"},
        {pos: [0, 0, 2], state: "mekanism:dynamic_tank"},
        {pos: [2, 1, 2], state: "mekanism:dynamic_tank"},
        {pos: [0, 1, 2], state: "mekanism:dynamic_tank"},
        {pos: [2, 2, 2], state: "mekanism:dynamic_tank"},
        {pos: [1, 2, 2], state: "mekanism:dynamic_tank"},
        {pos: [0, 2, 2], state: "mekanism:dynamic_tank"},
        {pos: [2, 0, 3], state: "mekanism:dynamic_tank"},
        {pos: [1, 0, 3], state: "mekanism:dynamic_tank"},
        {pos: [0, 0, 3], state: "mekanism:dynamic_tank"},
        {pos: [2, 1, 3], state: "mekanism:dynamic_tank"},
        {pos: [1, 1, 3], state: "mekanism:dynamic_tank"},
        {pos: [0, 1, 3], state: "mekanism:dynamic_tank"},
        {pos: [2, 2, 3], state: "mekanism:dynamic_tank"},
        {pos: [1, 2, 3], state: "mekanism:dynamic_tank"},
        {pos: [0, 2, 3], state: "mekanism:dynamic_tank"}
    ],
    entities: [],
    palette: [
        "ae2:cable_bus{light_level:0,waterlogged:false}",
        "ae2federation:switch",
        "ae2:energy_cell{fullness:4}",
        "ae2:drive{facing:north,spin:0}",
        "mekanism:dynamic_tank",
        "mekanism:dynamic_valve"
    ]
}
