{
    DataVersion: 3955,
    size: [6, 4, 5],
    data: [
        {pos: [5, 0, 0], state: "ae2:1k_crafting_storage{formed:true,powered:true}", nbt: {core: 1b, id: "ae2:crafting_storage", visual: {}}},
        {pos: [4, 0, 0], state: "ae2:cable_bus{light_level:0,waterlogged:false}", nbt: {cable: {id: "ae2:purple_smart_cable", visual: {channelsEast: 3, channelsUp: 3, channelsWest: 3, connections: ["up", "west", "east"], missingChannel: 0b, powered: 1b}}, hasRedstone: 2, id: "ae2:cable_bus", visual: {}, north: {id: "ae2:crafting_terminal", visual: {missingChannel: 0b, powered: 1b}}}},
        {pos: [3, 0, 0], state: "ae2federation:router"},
        {pos: [2, 0, 0], state: "ae2:cable_bus{light_level:0,waterlogged:false}", nbt: {cable: {id: "ae2:green_smart_cable", visual: {channelsEast: 1, channelsWest: 1, connections: ["west", "east"], missingChannel: 0b, powered: 1b}}, hasRedstone: 2, id: "ae2:cable_bus", visual: {}}},
        {pos: [1, 0, 0], state: "ae2:pattern_provider{push_direction:all}", nbt: {id: "ae2:pattern_provider", priority: 0, visual: {}}},
        {pos: [0, 0, 0], state: "ae2:molecular_assembler{powered:true}", nbt: {id: "ae2:molecular_assembler", visual: {}}},
        {pos: [3, 0, 1], state: "ae2:cable_bus{light_level:0,waterlogged:false}", nbt: {cable: {id: "ae2:light_blue_smart_cable", visual: {channelsNorth: 0, channelsUp: 0, connections: ["up", "north"], missingChannel: 0b, powered: 1b}}, hasRedstone: 2, id: "ae2:cable_bus", visual: {}}},
        {pos: [4, 0, 2], state: "mekanism:induction_casing"},
        {pos: [3, 0, 2], state: "mekanism:induction_casing"},
        {pos: [2, 0, 2], state: "mekanism:induction_casing"},
        {pos: [4, 0, 3], state: "mekanism:induction_casing"},
        {pos: [3, 0, 3], state: "mekanism:structural_glass"},
        {pos: [2, 0, 3], state: "mekanism:induction_casing"},
        {pos: [4, 0, 4], state: "mekanism:induction_casing"},
        {pos: [3, 0, 4], state: "mekanism:induction_casing"},
        {pos: [2, 0, 4], state: "mekanism:induction_casing"},
        {pos: [4, 1, 0], state: "ae2:drive{facing:north,spin:0}", nbt: {id: "ae2:drive", priority: 0, visual: {cell0: {id: "ae2:item_storage_cell_4k", state: "not_empty"}, cell1: {id: "ae2:item_storage_cell_4k", state: "not_empty"}, cell2: {id: "ae2:item_storage_cell_4k", state: "not_empty"}, cell3: {id: "ae2:item_storage_cell_4k", state: "not_empty"}}}},
        {pos: [3, 1, 1], state: "ae2:energy_acceptor"},
        {pos: [4, 1, 2], state: "mekanism:induction_casing"},
        {pos: [3, 1, 2], state: "mekanism:induction_port{active:true}"},
        {pos: [2, 1, 2], state: "mekanism:induction_casing"},
        {pos: [4, 1, 3], state: "mekanism:structural_glass"},
        {pos: [3, 1, 3], state: "mekanism:basic_induction_cell"},
        {pos: [2, 1, 3], state: "mekanism:structural_glass"},
        {pos: [4, 1, 4], state: "mekanism:induction_casing"},
        {pos: [3, 1, 4], state: "mekanism:structural_glass"},
        {pos: [2, 1, 4], state: "mekanism:induction_casing"},
        {pos: [4, 2, 2], state: "mekanism:induction_casing"},
        {pos: [3, 2, 2], state: "mekanism:structural_glass"},
        {pos: [2, 2, 2], state: "mekanism:induction_casing"},
        {pos: [4, 2, 3], state: "mekanism:structural_glass"},
        {pos: [3, 2, 3], state: "mekanism:basic_induction_provider"},
        {pos: [2, 2, 3], state: "mekanism:structural_glass"},
        {pos: [4, 2, 4], state: "mekanism:induction_casing"},
        {pos: [3, 2, 4], state: "mekanism:structural_glass"},
        {pos: [2, 2, 4], state: "mekanism:induction_casing"},
        {pos: [4, 3, 2], state: "mekanism:induction_casing"},
        {pos: [3, 3, 2], state: "mekanism:induction_casing"},
        {pos: [2, 3, 2], state: "mekanism:induction_casing"},
        {pos: [4, 3, 3], state: "mekanism:induction_casing"},
        {pos: [3, 3, 3], state: "mekanism:structural_glass"},
        {pos: [2, 3, 3], state: "mekanism:induction_casing"},
        {pos: [4, 3, 4], state: "mekanism:induction_casing"},
        {pos: [3, 3, 4], state: "mekanism:induction_casing"},
        {pos: [2, 3, 4], state: "mekanism:induction_casing"}
    ],
    entities: [],
    palette: [
        "ae2:1k_crafting_storage{formed:true,powered:true}",
        "ae2:cable_bus{light_level:0,waterlogged:false}",
        "ae2federation:router",
        "ae2:pattern_provider{push_direction:all}",
        "ae2:molecular_assembler{powered:true}",
        "mekanism:induction_casing",
        "mekanism:structural_glass",
        "ae2:drive{facing:north,spin:0}",
        "ae2:energy_acceptor",
        "mekanism:induction_port{active:true}",
        "mekanism:basic_induction_cell",
        "mekanism:basic_induction_provider"
    ]
}
