{
    DataVersion: 3955,
    size: [7, 3, 7],
    data: [
        {pos: [5, 0, 0], state: "ae2:drive{facing:north,spin:0}", nbt: {id: "ae2:drive", priority: 0, visual: {cell0: {id: "ae2:item_storage_cell_4k", state: "not_empty"}, cell1: {id: "ae2:item_storage_cell_4k", state: "not_empty"}, cell2: {id: "ae2:item_storage_cell_4k", state: "not_empty"}, cell3: {id: "ae2:item_storage_cell_4k", state: "not_empty"}}}},
        {pos: [4, 0, 0], state: "ae2:cable_bus{light_level:0,waterlogged:false}", nbt: {cable: {id: "ae2:purple_smart_cable", visual: {channelsEast: 3, channelsWest: 3, connections: ["west", "east"], missingChannel: 0b, powered: 1b}}, hasRedstone: 2, id: "ae2:cable_bus", visual: {}, north: {id: "ae2:crafting_terminal", visual: {missingChannel: 0b, powered: 1b}}}},
        {pos: [3, 0, 0], state: "ae2federation:router"},
        {pos: [2, 0, 0], state: "ae2:cable_bus{light_level:0,waterlogged:false}", nbt: {cable: {id: "ae2:green_smart_cable", visual: {channelsEast: 3, channelsWest: 3, connections: ["west", "east"], missingChannel: 0b, powered: 1b}}, hasRedstone: 2, id: "ae2:cable_bus", visual: {}, north: {id: "ae2:crafting_terminal", visual: {missingChannel: 0b, powered: 1b}}}},
        {pos: [1, 0, 0], state: "ae2:drive{facing:north,spin:0}", nbt: {id: "ae2:drive", priority: 0, visual: {cell0: {id: "ae2:item_storage_cell_4k", state: "not_empty"}, cell1: {id: "ae2:item_storage_cell_4k", state: "not_empty"}, cell2: {id: "ae2:item_storage_cell_4k", state: "not_empty"}, cell3: {id: "ae2:item_storage_cell_4k", state: "not_empty"}}}},
        {pos: [3, 0, 1], state: "ae2:cable_bus{light_level:0,waterlogged:false}", nbt: {cable: {id: "ae2:light_blue_smart_cable", visual: {channelsNorth: 1, channelsSouth: 1, channelsUp: 1, connections: ["up", "north", "south"], missingChannel: 0b, powered: 1b}}, hasRedstone: 2, id: "ae2:cable_bus", visual: {}}},
        {pos: [5, 0, 2], state: "extendedae_plus:super_assembler_matrix_frame{formed:true,powered:true,shape:block}"},
        {pos: [4, 0, 2], state: "extendedae_plus:super_assembler_matrix_frame{formed:true,powered:true,shape:column_x}"},
        {pos: [3, 0, 2], state: "extendedae_plus:super_assembler_matrix_frame{formed:true,powered:true,shape:column_x}"},
        {pos: [2, 0, 2], state: "extendedae_plus:super_assembler_matrix_frame{formed:true,powered:true,shape:column_x}"},
        {pos: [1, 0, 2], state: "extendedae_plus:super_assembler_matrix_frame{formed:true,powered:true,shape:block}"},
        {pos: [5, 0, 3], state: "extendedae_plus:super_assembler_matrix_frame{formed:true,powered:true,shape:column_z}"},
        {pos: [4, 0, 3], state: "extendedae:assembler_matrix_glass"},
        {pos: [3, 0, 3], state: "extendedae:assembler_matrix_glass"},
        {pos: [2, 0, 3], state: "extendedae:assembler_matrix_glass"},
        {pos: [1, 0, 3], state: "extendedae_plus:super_assembler_matrix_frame{formed:true,powered:true,shape:column_z}"},
        {pos: [5, 0, 4], state: "extendedae_plus:super_assembler_matrix_frame{formed:true,powered:true,shape:column_z}"},
        {pos: [4, 0, 4], state: "extendedae:assembler_matrix_glass"},
        {pos: [3, 0, 4], state: "extendedae:assembler_matrix_glass"},
        {pos: [2, 0, 4], state: "extendedae:assembler_matrix_glass"},
        {pos: [1, 0, 4], state: "extendedae_plus:super_assembler_matrix_frame{formed:true,powered:true,shape:column_z}"},
        {pos: [5, 0, 5], state: "extendedae_plus:super_assembler_matrix_frame{formed:true,powered:true,shape:column_z}"},
        {pos: [4, 0, 5], state: "extendedae:assembler_matrix_glass"},
        {pos: [3, 0, 5], state: "extendedae:assembler_matrix_glass"},
        {pos: [2, 0, 5], state: "extendedae:assembler_matrix_glass"},
        {pos: [1, 0, 5], state: "extendedae_plus:super_assembler_matrix_frame{formed:true,powered:true,shape:column_z}"},
        {pos: [5, 0, 6], state: "extendedae_plus:super_assembler_matrix_frame{formed:true,powered:true,shape:block}"},
        {pos: [4, 0, 6], state: "extendedae_plus:super_assembler_matrix_frame{formed:true,powered:true,shape:column_x}"},
        {pos: [3, 0, 6], state: "extendedae_plus:super_assembler_matrix_frame{formed:true,powered:true,shape:column_x}"},
        {pos: [2, 0, 6], state: "extendedae_plus:super_assembler_matrix_frame{formed:true,powered:true,shape:column_x}"},
        {pos: [1, 0, 6], state: "extendedae_plus:super_assembler_matrix_frame{formed:true,powered:true,shape:block}"},
        {pos: [5, 1, 0], state: "ae2:1k_crafting_storage{formed:true,powered:true}", nbt: {core: 1b, id: "ae2:crafting_storage", visual: {}}},
        {pos: [1, 1, 0], state: "ae2:1k_crafting_storage{formed:true,powered:true}", nbt: {core: 1b, id: "ae2:crafting_storage", visual: {}}},
        {pos: [3, 1, 1], state: "ae2:energy_cell{fullness:4}", nbt: {id: "ae2:energy_cell", internalCurrentPower: 200000.0d}},
        {pos: [5, 1, 2], state: "extendedae_plus:super_assembler_matrix_frame{formed:true,powered:true,shape:column_y}"},
        {pos: [4, 1, 2], state: "extendedae:assembler_matrix_glass"},
        {pos: [3, 1, 2], state: "extendedae:assembler_matrix_glass"},
        {pos: [2, 1, 2], state: "extendedae:assembler_matrix_glass"},
        {pos: [1, 1, 2], state: "extendedae_plus:super_assembler_matrix_frame{formed:true,powered:true,shape:column_y}"},
        {pos: [5, 1, 3], state: "extendedae:assembler_matrix_glass"},
        {pos: [4, 1, 3], state: "extendedae_plus:assembler_matrix_hybrid_plus{formed:true,powered:true}"},
        {pos: [3, 1, 3], state: "extendedae_plus:assembler_matrix_hybrid_plus{formed:true,powered:true}"},
        {pos: [2, 1, 3], state: "extendedae_plus:assembler_matrix_hybrid_plus{formed:true,powered:true}"},
        {pos: [1, 1, 3], state: "extendedae:assembler_matrix_glass"},
        {pos: [5, 1, 4], state: "extendedae:assembler_matrix_glass"},
        {pos: [4, 1, 4], state: "extendedae_plus:assembler_matrix_hybrid_plus{formed:true,powered:true}"},
        {pos: [3, 1, 4], state: "extendedae_plus:assembler_matrix_hybrid_plus{formed:true,powered:true}"},
        {pos: [2, 1, 4], state: "extendedae_plus:assembler_matrix_hybrid_plus{formed:true,powered:true}"},
        {pos: [1, 1, 4], state: "extendedae:assembler_matrix_glass"},
        {pos: [5, 1, 5], state: "extendedae:assembler_matrix_glass"},
        {pos: [4, 1, 5], state: "extendedae_plus:assembler_matrix_hybrid_plus{formed:true,powered:true}"},
        {pos: [3, 1, 5], state: "extendedae_plus:assembler_matrix_hybrid_plus{formed:true,powered:true}"},
        {pos: [2, 1, 5], state: "extendedae_plus:assembler_matrix_hybrid_plus{formed:true,powered:true}"},
        {pos: [1, 1, 5], state: "extendedae:assembler_matrix_glass"},
        {pos: [5, 1, 6], state: "extendedae_plus:super_assembler_matrix_frame{formed:true,powered:true,shape:column_y}"},
        {pos: [4, 1, 6], state: "extendedae:assembler_matrix_glass"},
        {pos: [3, 1, 6], state: "extendedae:assembler_matrix_glass"},
        {pos: [2, 1, 6], state: "extendedae:assembler_matrix_glass"},
        {pos: [1, 1, 6], state: "extendedae_plus:super_assembler_matrix_frame{formed:true,powered:true,shape:column_y}"},
        {pos: [5, 2, 2], state: "extendedae_plus:super_assembler_matrix_frame{formed:true,powered:true,shape:block}"},
        {pos: [4, 2, 2], state: "extendedae_plus:super_assembler_matrix_frame{formed:true,powered:true,shape:column_x}"},
        {pos: [3, 2, 2], state: "extendedae_plus:super_assembler_matrix_frame{formed:true,powered:true,shape:column_x}"},
        {pos: [2, 2, 2], state: "extendedae_plus:super_assembler_matrix_frame{formed:true,powered:true,shape:column_x}"},
        {pos: [1, 2, 2], state: "extendedae_plus:super_assembler_matrix_frame{formed:true,powered:true,shape:block}"},
        {pos: [5, 2, 3], state: "extendedae_plus:super_assembler_matrix_frame{formed:true,powered:true,shape:column_z}"},
        {pos: [4, 2, 3], state: "extendedae:assembler_matrix_glass"},
        {pos: [3, 2, 3], state: "extendedae:assembler_matrix_glass"},
        {pos: [2, 2, 3], state: "extendedae:assembler_matrix_glass"},
        {pos: [1, 2, 3], state: "extendedae_plus:super_assembler_matrix_frame{formed:true,powered:true,shape:column_z}"},
        {pos: [5, 2, 4], state: "extendedae_plus:super_assembler_matrix_frame{formed:true,powered:true,shape:column_z}"},
        {pos: [4, 2, 4], state: "extendedae:assembler_matrix_glass"},
        {pos: [3, 2, 4], state: "extendedae:assembler_matrix_glass"},
        {pos: [2, 2, 4], state: "extendedae:assembler_matrix_glass"},
        {pos: [1, 2, 4], state: "extendedae_plus:super_assembler_matrix_frame{formed:true,powered:true,shape:column_z}"},
        {pos: [5, 2, 5], state: "extendedae_plus:super_assembler_matrix_frame{formed:true,powered:true,shape:column_z}"},
        {pos: [4, 2, 5], state: "extendedae:assembler_matrix_glass"},
        {pos: [3, 2, 5], state: "extendedae:assembler_matrix_glass"},
        {pos: [2, 2, 5], state: "extendedae:assembler_matrix_glass"},
        {pos: [1, 2, 5], state: "extendedae_plus:super_assembler_matrix_frame{formed:true,powered:true,shape:column_z}"},
        {pos: [5, 2, 6], state: "extendedae_plus:super_assembler_matrix_frame{formed:true,powered:true,shape:block}"},
        {pos: [4, 2, 6], state: "extendedae_plus:super_assembler_matrix_frame{formed:true,powered:true,shape:column_x}"},
        {pos: [3, 2, 6], state: "extendedae_plus:super_assembler_matrix_frame{formed:true,powered:true,shape:column_x}"},
        {pos: [2, 2, 6], state: "extendedae_plus:super_assembler_matrix_frame{formed:true,powered:true,shape:column_x}"},
        {pos: [1, 2, 6], state: "extendedae_plus:super_assembler_matrix_frame{formed:true,powered:true,shape:block}"}
    ],
    entities: [],
    palette: [
        "ae2:drive{facing:north,spin:0}",
        "ae2:cable_bus{light_level:0,waterlogged:false}",
        "ae2federation:router",
        "extendedae_plus:super_assembler_matrix_frame{formed:true,powered:true,shape:block}",
        "extendedae_plus:super_assembler_matrix_frame{formed:true,powered:true,shape:column_x}",
        "extendedae_plus:super_assembler_matrix_frame{formed:true,powered:true,shape:column_z}",
        "extendedae:assembler_matrix_glass",
        "ae2:1k_crafting_storage{formed:true,powered:true}",
        "ae2:energy_cell{fullness:4}",
        "extendedae_plus:super_assembler_matrix_frame{formed:true,powered:true,shape:column_y}",
        "extendedae_plus:assembler_matrix_hybrid_plus{formed:true,powered:true}"
    ]
}
